рџ”Ѓ Р—Р°РїСѓСЃРє РїРѕРІРЅРѕРіРѕ С†РёРєР»Сѓ РЅР°РІС‡Р°РЅРЅСЏ Р±РѕС‚Р°... 
рџ”„ РљРѕРЅРІРµСЂС‚Р°С†С–СЏ TXT в†’ JSONL 
Traceback (most recent call last):
  File "C:\Users\acer\Documents\project\utils.py", line 61, in <module>
    real_chunks = json.load(f)
  File "C:\Users\acer\AppData\Local\Programs\Python\Python313\Lib\json\__init__.py", line 293, in load
    return loads(fp.read(),
        cls=cls, object_hook=object_hook,
        parse_float=parse_float, parse_int=parse_int,
        parse_constant=parse_constant, object_pairs_hook=object_pairs_hook, **kw)
  File "C:\Users\acer\AppData\Local\Programs\Python\Python313\Lib\json\__init__.py", line 346, in loads
    return _default_decoder.decode(s)
           ~~~~~~~~~~~~~~~~~~~~~~~^^^
  File "C:\Users\acer\AppData\Local\Programs\Python\Python313\Lib\json\decoder.py", line 348, in decode
    raise JSONDecodeError("Extra data", s, end)
json.decoder.JSONDecodeError: Extra data: line 2 column 1 (char 2864)

During handling of the above exception, another exception occurred:

Traceback (most recent call last):
  File "C:\Users\acer\Documents\project\scripts\convert_real_dialogs.py", line 11, in <module>
    from utils import log
  File "C:\Users\acer\Documents\project\utils.py", line 78, in <module>
    print(f"\u26a0\ufe0f Не вдалося завантажити real_dialogs: {e}")
    ~~~~~^^^^^^^^^^^^^^^^^^^^^^^^^^^^^^^^^^^^^^^^^^^^^^^^
  File "C:\Users\acer\AppData\Local\Programs\Python\Python313\Lib\encodings\cp1251.py", line 19, in encode
    return codecs.charmap_encode(input,self.errors,encoding_table)[0]
           ~~~~~~~~~~~~~~~~~~~~~^^^^^^^^^^^^^^^^^^^^^^^^^^^^^^^^^^
UnicodeEncodeError: 'charmap' codec can't encode characters in position 0-1: character maps to <undefined>
